<?xml version='1.0'?>

<robot name="noor_robot" xmlns:xacro="http://www.ros.org/wiki/xacro">
  <link name="base_footprint">
  </link>
  
  <joint name="base_footprint_joint" type="fixed">
      <parent link="base_footprint"/>
      <child link="base_link"/>
  </joint>



  <link
    name="base_link">
    <inertial>
      <origin
        xyz="-0.00649008278812091 -4.90170912235965E-05 0.164700039468933"
        rpy="0 0 0" />
      <mass
        value="60.7892515854454" />
      <inertia
        ixx="1.67020512014057"
        ixy="2.36055198816332E-05"
        ixz="0.00950828317435565"
        iyy="1.39465739639809"
        iyz="4.88396318358833E-05"
        izz="2.23596193011423" />
    </inertial>
    <visual>
      <origin
        xyz="0 0 0"
        rpy="0 0 0" />
      <geometry>
        <mesh
          filename="package://noor_robot/meshes/base_link.STL" />
      </geometry>
      <material
        name="">
        <color
          rgba="1 1 1 1" />
      </material>
    </visual>
    <collision>
      <origin
        xyz="0 0 0"
        rpy="0 0 0" />
      <geometry>
        <mesh
          filename="package://noor_robot/meshes/base_link.STL" />
      </geometry>
    </collision>
  </link>
  <link
    name="right_wheel">
    <inertial>
      <origin
        xyz="2.9308E-10 0.01227 -1.0991E-09"
        rpy="0 0 0" />
      <mass
        value="0.19565" />
      <inertia
        ixx="0.00028146"
        ixy="-7.1189E-13"
        ixz="-2.7736E-12"
        iyy="0.00054078"
        iyz="2.667E-12"
        izz="0.00028146" />
    </inertial>
    <visual>
      <origin
        xyz="0 0 0"
        rpy="0 0 0" />
      <geometry>
        <mesh
          filename="package://noor_robot/meshes/right_wheel.STL" />
      </geometry>
      <material
        name="">
        <color
          rgba="0.79216 0.81961 0.93333 1" />
      </material>
    </visual>
    <collision>
      <origin
        xyz="0 0 0"
        rpy="0 0 0" />
      <geometry>
        <mesh
          filename="package://noor_robot/meshes/right_wheel.STL" />
      </geometry>
    </collision>
  </link>
  <joint
    name="right_wheel_joint"
    type="continuous">
    <origin
      xyz="0.035969 -0.225 0.02"
      rpy="0 0 0" />
    <parent
      link="base_link" />
    <child
      link="right_wheel" />
    <axis
      xyz="0 1 0" />
  </joint>
  <link
    name="left_wheel">
    <inertial>
      <origin
        xyz="1.092E-09 0.01227 3.1855E-10"
        rpy="0 0 0" />
      <mass
        value="0.19565" />
      <inertia
        ixx="0.00028146"
        ixy="-2.6498E-12"
        ixz="2.9947E-12"
        iyy="0.00054078"
        iyz="-7.7369E-13"
        izz="0.00028146" />
    </inertial>
    <visual>
      <origin
        xyz="0 0 0"
        rpy="0 0 0" />
      <geometry>
        <mesh
          filename="package://noor_robot/meshes/left_wheel.STL" />
      </geometry>
      <material
        name="">
        <color
          rgba="0.79216 0.81961 0.93333 1" />
      </material>
    </visual>
    <collision>
      <origin
        xyz="0 0 0"
        rpy="0 0 0" />
      <geometry>
        <mesh
          filename="package://noor_robot/meshes/left_wheel.STL" />
      </geometry>
    </collision>
  </link>
  <joint
    name="left_wheel_joint"
    type="continuous">
    <origin
      xyz="0.035969 0.195 0.02"
      rpy="0 0 0" />
    <parent
      link="base_link" />
    <child
      link="left_wheel" />
    <axis
      xyz="0 1 0" />
  </joint>
  <link
    name="caster_wheel">
    <inertial>
      <origin
        xyz="1.11022302462516E-16 -0.00950000000000004 0.00731386708659532"
        rpy="0 0 0" />
      <mass
        value="0.0388650305296306" />
      <inertia
        ixx="9.41211622125365E-06"
        ixy="-6.21441056447855E-12"
        ixz="-2.17608471242286E-20"
        iyy="1.46975626425746E-05"
        iyz="-5.67686169142394E-21"
        izz="9.37855273604109E-06" />
    </inertial>
    <visual>
      <origin
        xyz="0 0 0"
        rpy="0 0 0" />
      <geometry>
        <mesh
          filename="package://noor_robot/meshes/caster_wheel.STL" />
      </geometry>
      <material
        name="">
        <color
          rgba="0.792156862745098 0.819607843137255 0.933333333333333 1" />
      </material>
    </visual>
    <collision>
      <origin
        xyz="0 0 0"
        rpy="0 0 0" />
      <geometry>
        <mesh
          filename="package://noor_robot/meshes/caster_wheel.STL" />
      </geometry>
    </collision>
  </link>
  <joint
    name="caster_wheel_joint"
    type="fixed">
    <origin
      xyz="-0.14362 0.013 -0.0184"
      rpy="0 0 0" />
    <parent
      link="base_link" />
    <child
      link="caster_wheel" />
    <axis
      xyz="0 0 0" />
  </joint>
  <link
    name="laser">
    <inertial>
      <origin
        xyz="-0.000966031609306306 7.35066081083979E-05 0.00978516579269328"
        rpy="0 0 0" />
      <mass
        value="0.163065240500782" />
      <inertia
        ixx="6.07633272001178E-05"
        ixy="-6.99095672430013E-09"
        ixz="-2.40709934137094E-07"
        iyy="6.04003022999732E-05"
        iyz="1.66846380987903E-08"
        izz="0.000107588752845482" />
    </inertial>
    <visual>
      <origin
        xyz="0 0 0"
        rpy="0 0 0" />
      <geometry>
        <mesh
          filename="package://noor_robot/meshes/laser.STL" />
      </geometry>
      <material
        name="">
        <color
          rgba="0.792156862745098 0.819607843137255 0.933333333333333 1" />
      </material>
    </visual>
    <collision>
      <origin
        xyz="0 0 0"
        rpy="0 0 0" />
      <geometry>
        <mesh
          filename="package://noor_robot/meshes/laser.STL" />
      </geometry>
    </collision>
  </link>
  <joint
    name="laser_joint"
    type="fixed">
    <origin
      xyz="0.053113 0 0.2723"
      rpy="0 0 0" />
    <parent
      link="base_link" />
    <child
      link="laser" />
    <axis
      xyz="0 0 0" />
  </joint>
  <link
    name="camera">
    <inertial>
      <origin
        xyz="-0.0121705494191511 -0.00219335337008569 -4.70795722447015E-05"
        rpy="0 0 0" />
      <mass
        value="0.0482048942053294" />
      <inertia
        ixx="2.73978020880107E-05"
        ixy="-4.25491567726878E-07"
        ixz="-7.54361854725822E-09"
        iyy="3.35066077371062E-06"
        iyz="-2.19310424974189E-09"
        izz="2.66585220556753E-05" />
    </inertial>
    <visual>
      <origin
        xyz="0 0 0"
        rpy="0 0 0" />
      <geometry>
        <mesh
          filename="package://noor_robot/meshes/camera.STL" />
      </geometry>
      <material
        name="">
        <color
          rgba="0.776470588235294 0.756862745098039 0.737254901960784 1" />
      </material>
    </visual>
    <collision>
      <origin
        xyz="0 0 0"
        rpy="0 0 0" />
      <geometry>
        <mesh
          filename="package://noor_robot/meshes/camera.STL" />
      </geometry>
    </collision>
  </link>
  <joint
    name="camera_joint"
    type="fixed">
    <origin
      xyz="0.0020866 0.00081908 1.3241"
      rpy="0 -0.17453 0" />
    <parent
      link="base_link" />
    <child
      link="camera" />
    <axis
      xyz="0 0 0" />
  </joint>
  <link
    name="tablet">
    <inertial>
      <origin
        xyz="0 0 0"
        rpy="0 0 0" />
      <mass
        value="0" />
      <inertia
        ixx="0"
        ixy="0"
        ixz="0"
        iyy="0"
        iyz="0"
        izz="0" />
    </inertial>
    <visual>
      <origin
        xyz="0 0 0"
        rpy="0 0 0" />
      <geometry>
        <mesh
          filename="package://noor_robot/meshes/tablet.STL" />
      </geometry>
      <material
        name="">
        <color
          rgba="1 1 1 1" />
      </material>
    </visual>
    <collision>
      <origin
        xyz="0 0 0"
        rpy="0 0 0" />
      <geometry>
        <mesh
          filename="package://noor_robot/meshes/tablet.STL" />
      </geometry>
    </collision>
  </link>
  <joint
    name="tablet_joint"
    type="fixed">
    <origin
      xyz="0.013835 -0.0027358 1.246"
      rpy="0 -0.17453 0" />
    <parent
      link="base_link" />
    <child
      link="tablet" />
    <axis
      xyz="0 0 0" />
  </joint>

  <link name="imu_link">
    <collision>
    <origin xyz="0 0 0.1" rpy="0 0 0"/>
    <geometry>
        <box size="0.02 0.02 0.02"/>
    </geometry>
    </collision>

    <visual>
    <origin xyz="0 0 0.1" rpy="0 0 0"/>
    <geometry>
        <box size="0.02 0.02 0.02"/>
    </geometry>
    <material name="orange"/>
    </visual>

    <inertial>
    <origin xyz="0 0 1" rpy="0 0 0"/>
    <mass value="1"/>
    <inertia
        ixx="1.0" ixy="0.0" ixz="0.0"
        iyy="1.0" iyz="0.0"
        izz="1.0"/>
    </inertial>
</link>
<joint name="imu_joint" type="fixed">
    <origin xyz="0.0 0.0 0.0" rpy="0.0 0.0 0.0"/>
    <parent link="base_link"/>
    <child link="imu_link"/>
</joint>

</robot>
